<?xml version="1.0" ?>
<!-- Generated using onshape-to-robot -->
<mujoco model="hiro-mujoco">
  <option timestep="0.004" gravity="0 0 -9.81" iterations="50" tolerance="1e-4"/>
  <compiler angle="radian" meshdir="assets" autolimits="true"/>
  <default>
    <default class="hiro-mujoco">
      <joint frictionloss="0.1" armature="0.005"/>
      <position kp="50" dampratio="1"/>
      <default class="visual">
        <geom type="mesh" contype="0" conaffinity="0" group="2"/>
      </default>
      <default class="collision">
        <geom group="3"/>
      </default>
    </default>
  </default>
  <worldbody>
    <!-- Link torso_kidsize25 -->
    <body name="torso_kidsize25" pos="0 0 0" quat="1 0 0 0" childclass="hiro-mujoco">
      <freejoint name="torso_kidsize25_freejoint"/>
      <site name="torso_imu_site" pos="0 0 0" size="0.01"/>
      <inertial pos="-5.43423e-06 -0.0200969 0.0976927" mass="2.16719" fullinertia="0.00929033 0.00982507 0.00934245 -9.38024e-07 8.09787e-07 0.000706149"/>
      <!-- Part mx_64t_mir1 -->
      <geom type="mesh" class="collision" pos="0.0495 -0.0149156 0.0445065" quat="1 5.71071e-15 1.07692e-13 -3.27924e-15" mesh="mx_64t_mir1" material="mx_64t_mir1_material"/>
      <!-- Part mx_64t -->
      <geom type="mesh" class="collision" pos="-0.0495 -0.0149172 0.0445065" quat="1.07637e-13 -3.3625e-15 -1 -5.70951e-15" mesh="mx_64t" material="mx_64t_material"/>
      <!-- Part mx_28 -->
      <geom type="mesh" class="collision" pos="-0.0435004 -0.0845737 0.169212" quat="0.5 -0.5 -0.5 -0.5" mesh="mx_28" material="mx_28_material"/>
      <!-- Part mx_28_2 -->
      <geom type="mesh" class="collision" pos="-0.00781868 0.0207067 0.15592" quat="7.82454e-14 7.38339e-14 -0.707107 0.707107" mesh="mx_28" material="mx_28_material"/>
      <!-- Part mx_28_3 -->
      <geom type="mesh" class="collision" pos="0.0435004 -0.0845737 0.153401" quat="0.5 -0.5 0.5 0.5" mesh="mx_28" material="mx_28_material"/>
      <!-- Part upper_floor -->
      <geom type="mesh" class="collision" pos="-0.064378 -0.0627188 0.140507" quat="0.5 -0.5 0.5 -0.5" mesh="upper_floor" material="upper_floor_material"/>
      <!-- Part 2nd_floor -->
      <geom type="mesh" class="collision" pos="0.064378 -0.0627188 0.0715065" quat="0.5 0.5 0.5 0.5" mesh="2nd_floor" material="2nd_floor_material"/>
      <!-- Part front_pillar -->
      <geom type="mesh" class="collision" pos="-0.072 0.0462822 0.0795065" quat="0.707107 0.707107 7.38298e-14 -7.83929e-14" mesh="front_pillar" material="front_pillar_material"/>
      <!-- Part front_pillar_2 -->
      <geom type="mesh" class="collision" pos="0.072 0.0392822 0.0795065" quat="7.37575e-14 -7.84322e-14 -0.707107 -0.707107" mesh="front_pillar" material="front_pillar_material"/>
      <!-- Part front_pillar_3 -->
      <geom type="mesh" class="collision" pos="0.072 -0.0707178 0.0795065" quat="7.38729e-14 -7.84322e-14 -0.707107 -0.707107" mesh="front_pillar" material="front_pillar_material"/>
      <!-- Part front_pillar_4 -->
      <geom type="mesh" class="collision" pos="-0.072 -0.0637178 0.132507" quat="0.5 -0.5 0.5 -0.5" mesh="front_pillar" material="front_pillar_material"/>
      <!-- Part pcnel_exch -->
      <geom type="mesh" class="collision" pos="-1.36807e-13 -0.0142178 0.137507" quat="0.5 -0.5 0.5 -0.5" mesh="pcnel_exch" material="pcnel_exch_material"/>
      <!-- Part spacer_bracket_id_1_19_2_mir -->
      <geom type="mesh" class="collision" pos="0.0366867 -0.0407649 0.158268" quat="7.38733e-14 -7.83144e-14 -0.707107 -0.707107" mesh="spacer_bracket_id_1_19_2_mir" material="spacer_bracket_id_1_19_2_mir_material"/>
      <!-- Part handle_bracket_kidsize -->
      <geom type="mesh" class="collision" pos="0.068 0.00858119 0.144507" quat="0.5 -0.5 0.5 -0.5" mesh="handle_bracket_kidsize" material="handle_bracket_kidsize_material"/>
      <!-- Part almi_5mm_bracket_servo_1_2_left -->
      <geom type="mesh" class="collision" pos="0.0411367 -0.0455112 0.163369" quat="7.38731e-14 -7.82752e-14 -0.707107 -0.707107" mesh="almi_5mm_bracket_servo_1_2_left" material="almi_5mm_bracket_servo_1_2_left_material"/>
      <!-- Part handle -->
      <geom type="mesh" class="collision" pos="1.14631e-14 0.0580812 0.197506" quat="6.15025e-15 -0.707107 -1.77636e-15 0.707107" mesh="handle" material="handle_material"/>
      <!-- Part holder_bumper_upper -->
      <geom type="mesh" class="collision" pos="-0.0667133 0.0621524 0.213757" quat="7.39527e-14 -7.83537e-14 -0.707107 -0.707107" mesh="holder_bumper_upper" material="holder_bumper_upper_material"/>
      <!-- Part handler_holder_siber -->
      <geom type="mesh" class="collision" pos="-0.0585 -0.0594188 0.102506" quat="0.5 0.5 0.5 0.5" mesh="handler_holder_siber" material="handler_holder_siber_material"/>
      <!-- Part bracket_1_2_lower_left -->
      <geom type="mesh" class="collision" pos="0.0664867 -0.0457677 0.165055" quat="0.707107 0.707107 7.38298e-14 -7.83537e-14" mesh="bracket_1_2_lower_left" material="bracket_1_2_lower_left_material"/>
      <!-- Part front_upper_bumper -->
      <geom type="mesh" class="collision" pos="-0.0712133 -0.0912838 0.160907" quat="0.707107 0.707107 7.39409e-14 -7.84322e-14" mesh="front_upper_bumper" material="front_upper_bumper_material"/>
      <!-- Part petg_5_19_mx28_seating -->
      <geom type="mesh" class="collision" pos="0.0124903 -0.0576838 0.147757" quat="0.707107 -0.707107 7.84928e-14 7.39124e-14" mesh="petg_5_19_mx28_seating" material="petg_5_19_mx28_seating_material"/>
      <!-- Part almi_5mm_bracket_servo_1_2 -->
      <geom type="mesh" class="collision" pos="-0.0411367 -0.0455112 0.163369" quat="0.707107 0.707107 7.38298e-14 -7.83929e-14" mesh="almi_5mm_bracket_servo_1_2" material="almi_5mm_bracket_servo_1_2_material"/>
      <!-- Part spacer_bracket_id_1_19_2 -->
      <geom type="mesh" class="collision" pos="-0.0366867 -0.0407649 0.158268" quat="0.707107 0.707107 7.38298e-14 -7.83144e-14" mesh="spacer_bracket_id_1_19_2" material="spacer_bracket_id_1_19_2_material"/>
      <!-- Part handler_holder_siber_2 -->
      <geom type="mesh" class="collision" pos="0.0685 -0.0594188 0.102506" quat="0.5 0.5 0.5 0.5" mesh="handler_holder_siber" material="handler_holder_siber_material"/>
      <!-- Part front_upper_bumper_mir -->
      <geom type="mesh" class="collision" pos="0.0709867 -0.0912838 0.160907" quat="7.39514e-14 -7.83537e-14 -0.707107 -0.707107" mesh="front_upper_bumper_mir" material="front_upper_bumper_mir_material"/>
      <!-- Part handle_bracket_kidsize_2 -->
      <geom type="mesh" class="collision" pos="-0.068 0.00858119 0.144507" quat="0.5 -0.5 0.5 -0.5" mesh="handle_bracket_kidsize" material="handle_bracket_kidsize_material"/>
      <!-- Part bracket_1_2_lower -->
      <geom type="mesh" class="collision" pos="-0.0664867 -0.0457677 0.165055" quat="7.38726e-14 -7.83537e-14 -0.707107 -0.707107" mesh="bracket_1_2_lower" material="bracket_1_2_lower_material"/>
      <!-- Part bumper_front_lower_mir -->
      <geom type="mesh" class="collision" pos="0.0685 -0.0939156 0.0494707" quat="7.3677e-14 -7.83144e-14 -0.707107 -0.707107" mesh="bumper_front_lower_mir" material="bumper_front_lower_mir_material"/>
      <!-- Part spacer_106_64_mir2 -->
      <geom type="mesh" class="collision" pos="-0.0478366 -0.0405746 0.0615065" quat="0.5 0.5 -0.5 0.5" mesh="spacer_106_64_mir2" material="spacer_106_64_mir2_material"/>
      <!-- Part holder_lower_bracket_mir -->
      <geom type="mesh" class="collision" pos="0.0407975 -0.0654156 0.0911788" quat="7.8314e-14 7.37554e-14 -0.707107 0.707107" mesh="holder_lower_bracket_mir" material="holder_lower_bracket_mir_material"/>
      <!-- Part almi_2mm_floor_2nd__1 -->
      <geom type="mesh" class="collision" pos="-0.00365951 -0.0159644 0.0275065" quat="0.707107 6.40286e-15 0.707107 1.7225e-15" mesh="almi_2mm_floor_2nd__1" material="almi_2mm_floor_2nd__1_material"/>
      <!-- Part spacer_106_64_mir2_mir -->
      <geom type="mesh" class="collision" pos="0.0478366 -0.040573 0.0615065" quat="0.5 -0.5 -0.5 -0.5" mesh="spacer_106_64_mir2_mir" material="spacer_106_64_mir2_mir_material"/>
      <!-- Part back_bumper -->
      <geom type="mesh" class="collision" pos="0.0647 0.0287838 0.0485065" quat="0.5 0.5 0.5 0.5" mesh="back_bumper" material="back_bumper_material"/>
      <!-- Part xt_bracket -->
      <geom type="mesh" class="collision" pos="0.0308 0.0417838 0.0275065" quat="3.27924e-15 1.0764e-13 -5.77316e-15 1" mesh="xt_bracket" material="xt_bracket_material"/>
      <!-- Part battery_holder -->
      <geom type="mesh" class="collision" pos="6.3411e-10 -0.0702162 0.0225065" quat="0.5 0.5 0.5 0.5" mesh="battery_holder" material="battery_holder_material"/>
      <!-- Part back_bumper_2 -->
      <geom type="mesh" class="collision" pos="-0.0647 0.0287838 0.0485065" quat="0.5 -0.5 -0.5 0.5" mesh="back_bumper" material="back_bumper_material"/>
      <!-- Part bracket_back_bumper -->
      <geom type="mesh" class="collision" pos="0.0452 0.0307838 0.0495065" quat="7.37752e-14 -7.84916e-14 -0.707107 -0.707107" mesh="bracket_back_bumper" material="bracket_back_bumper_material"/>
      <!-- Part holder_lower_bracket -->
      <geom type="mesh" class="collision" pos="-0.0407975 -0.0654172 0.0911788" quat="0.707107 -0.707107 7.83817e-14 7.39378e-14" mesh="holder_lower_bracket" material="holder_lower_bracket_material"/>
      <!-- Part xt_bracket_2 -->
      <geom type="mesh" class="collision" pos="-0.0308 0.0377838 0.0275065" quat="1 5.71521e-15 1.07692e-13 -3.27997e-15" mesh="xt_bracket" material="xt_bracket_material"/>
      <!-- Part bumper_front_lower -->
      <geom type="mesh" class="collision" pos="-0.0685 -0.0939172 0.0494707" quat="0.707107 0.707107 7.37188e-14 -7.84616e-14" mesh="bumper_front_lower" material="bumper_front_lower_material"/>
      <!-- Part bracket_back_bumper_mir -->
      <geom type="mesh" class="collision" pos="-0.0452 0.0307838 0.0495065" quat="0.707107 0.707107 7.36078e-14 -7.83728e-14" mesh="bracket_back_bumper_mir" material="bracket_back_bumper_mir_material"/>
      <!-- Part torso_kidsize25_parts -->
      <geom type="mesh" class="visual" pos="-5.43423e-06 -0.0200969 0.0976927" quat="1 0 0 0" mesh="torso_kidsize25_visual" material="torso_kidsize25_visual_material"/>
      <!-- Link neck -->
      <body name="neck" pos="8.67185e-05 -0.0446832 0.184707" quat="0.707107 8.00565e-14 7.21645e-14 0.707107">
        <!-- Joint from torso_kidsize25 to neck -->
        <joint axis="0 0 1" name="neck_yaw" type="hinge" range="-3.141592653589793 3.141592653589793" frictionloss="0.1"/>
        <inertial pos="2.39298e-07 1.20831e-17 0.00879985" mass="0.0128985" fullinertia="5.01235e-06 2.39998e-06 4.13467e-06 2.63324e-11 -9.38605e-13 1.16467e-21"/>
        <!-- Part almi_4mm_neck_bracket -->
        <geom type="mesh" class="collision" pos="0.0128945 -0.0185 0" quat="0.707107 0.707107 0 -2.18424e-31" mesh="almi_4mm_neck_bracket" material="almi_4mm_neck_bracket_material"/>
        <!-- Part carbon_2mm_neck_side_plate -->
        <geom type="mesh" class="collision" pos="5e-07 -0.0205 0.02" quat="0.707107 0.707107 -0 8.14871e-30" mesh="carbon_2mm_neck_side_plate" material="carbon_2mm_neck_side_plate_material"/>
        <!-- Part carbon_2mm_neck_side_plate_2 -->
        <geom type="mesh" class="collision" pos="-2.77556e-17 0.0225 0.02" quat="0.707107 0.707107 -0 3.39385e-31" mesh="carbon_2mm_neck_side_plate" material="carbon_2mm_neck_side_plate_material"/>
        <!-- Part neck_parts -->
        <geom type="mesh" class="visual" pos="2.39298e-07 1.48807e-17 0.00879985" quat="0.707107 -8.00566e-14 -7.22755e-14 -0.707107" mesh="neck_visual" material="neck_visual_material"/>
        <!-- Link head -->
        <body name="head" pos="5e-07 -0.0205 0.037" quat="0.5 -0.5 -0.5 -0.5">
          <!-- Joint from neck to head -->
          <joint axis="0 0 1" name="neck_pitch" type="hinge" range="-1.5707963267948966 0.39269908169872414" frictionloss="0.1"/>
          <inertial pos="0.0315459 -0.00214801 0.0205645" mass="0.371554" fullinertia="0.000238323 0.000308835 0.000217343 4.47308e-05 -2.28198e-07 -2.79152e-07"/>
          <!-- Part petg_2mm_headbracket_old -->
          <geom type="mesh" class="collision" pos="-0.0064 0.0265 0.0386" quat="0.5 0.5 0.5 -0.5" mesh="petg_2mm_headbracket_old" material="petg_2mm_headbracket_old_material"/>
          <!-- Part camera_logitech_c920_offset_2mm -->
          <geom type="mesh" class="collision" pos="0.0256 0.00182638 0.06759" quat="0.5 0.5 0.5 -0.5" mesh="camera_logitech_c920_offset_2mm" material="camera_logitech_c920_offset_2mm_material"/>
          <!-- Part camera_frame -->
          <geom type="mesh" class="collision" pos="0.0251 -0.0215 0.0535485" quat="5.71231e-18 0.707107 0.707107 -1.07591e-17" mesh="camera_frame" material="camera_frame_material"/>
          <!-- Part mx_28_4 -->
          <geom type="mesh" class="collision" pos="0.0079054 0.0653899 0.0287863" quat="0.707107 0.707107 -0 -1.04845e-30" mesh="mx_28" material="mx_28_material"/>
          <!-- Part petg_2mm_rotatingheadbracket -->
          <geom type="mesh" class="collision" pos="-0.0064 0.0265 0.0386" quat="0.5 0.5 0.5 -0.5" mesh="petg_2mm_rotatingheadbracket" material="petg_2mm_rotatingheadbracket_material"/>
          <!-- Part head_parts -->
          <geom type="mesh" class="visual" pos="0.0315459 -0.00214801 0.0205645" quat="0.707107 -1.69026e-14 0.707107 2.22032e-14" mesh="head_visual" material="head_visual_material"/>
        </body>
      </body>
      <!-- Link almi2_view_6_7__arm_bracket -->
      <body name="almi2_view_6_7__arm_bracket" pos="-0.0722867 -0.0191838 0.161307" quat="0.5 -0.5 0.5 -0.5">
        <!-- Joint from torso_kidsize25 to almi2_view_6_7__arm_bracket -->
        <joint axis="0 0 1" name="right_shoulder_pitch" type="hinge" range="-3.141592653589793 3.141592653589793" frictionloss="0.1"/>
        <inertial pos="-9.36751e-17 0.00223841 -0.00829596" mass="0.0151289" fullinertia="2.57897e-06 5.57377e-06 5.85595e-06 3.24106e-38 6.75078e-37 4.04961e-07"/>
        <!-- Part almi2_view_6_7__arm_bracket -->
        <geom type="mesh" class="collision" pos="0.0185 -0.012 -0.002" quat="0.707107 0.707107 -0 2.82962e-32" mesh="almi2_view_6_7__arm_bracket" material="almi2_view_6_7__arm_bracket_material"/>
        <!-- Part almi2_view_6_7__arm_bracket_parts -->
        <geom type="mesh" class="visual" pos="-9.71445e-17 0.00223841 -0.00829596" quat="0.5 0.5 -0.5 0.5" mesh="almi2_view_6_7__arm_bracket_visual" material="almi2_view_6_7__arm_bracket_visual_material"/>
        <!-- Link right_upperhand -->
        <body name="right_upperhand" pos="0.0205 0.0147498 -0.0268034" quat="0.5 0.5 0.5 0.5">
          <!-- Joint from almi2_view_6_7__arm_bracket to right_upperhand -->
          <joint axis="0 0 1" name="right_shoulder_roll" type="hinge" range="-0.7853981633974483 2.356194490192345" frictionloss="0.1"/>
          <inertial pos="-4.16556e-05 -0.0497057 -0.0229115" mass="0.178" fullinertia="0.000293103 3.4849e-05 0.00029267 -7.35413e-07 -2.0111e-08 -1.67161e-05"/>
          <!-- Part mx_28_5 -->
          <geom type="mesh" class="collision" pos="0.00818918 -0.0341201 -0.0335054" quat="0.5 0.5 0.5 -0.5" mesh="mx_28" material="mx_28_material"/>
          <!-- Part mx_28_6 -->
          <geom type="mesh" class="collision" pos="0.0079054 -0.0653899 -0.0287863" quat="0.707107 -0.707107 0 0" mesh="mx_28" material="mx_28_material"/>
          <!-- Part almi2_view_13__14__arm -->
          <geom type="mesh" class="collision" pos="-0.0819971 -0.058605 -0.0256" quat="1 -0 -1.11022e-16 1.94289e-16" mesh="almi2_view_13__14__arm" material="almi2_view_13__14__arm_material"/>
          <!-- Part right_upperhand_parts -->
          <geom type="mesh" class="visual" pos="-4.16556e-05 -0.0497057 -0.0229115" quat="0.5 -0.5 -0.5 0.5" mesh="right_upperhand_visual" material="right_upperhand_visual_material"/>
          <!-- Link right_lowerhand -->
          <body name="right_lowerhand" pos="-0.0205971 -0.09951 -0.0256" quat="0.707107 -2.16914e-14 0.707107 -2.16131e-14">
            <!-- Joint from right_upperhand to right_lowerhand -->
            <joint axis="0 0 1" name="right_elbow" type="hinge" range="-2.356194490192345 2.356194490192345" frictionloss="0.1"/>
            <inertial pos="-0.00130389 -0.103918 0.0103596" mass="0.149258" fullinertia="0.000225269 5.61474e-05 0.000240431 -7.02224e-06 -1.20544e-07 -3.26703e-05"/>
            <!-- Part almi_4_5mm_connector_lower_arm_kidsize -->
            <geom type="mesh" class="collision" pos="0.00225 -0.0405 0" quat="3.92523e-17 -0 0.707107 0.707107" mesh="almi_4_5mm_connector_lower_arm_kidsize" material="almi_4_5mm_connector_lower_arm_kidsize_material"/>
            <!-- Part carbon_2mm_arm_kidsize_1 -->
            <geom type="mesh" class="collision" pos="0 0 0" quat="0.5 0.5 0.5 -0.5" mesh="carbon_2mm_arm_kidsize_1" material="carbon_2mm_arm_kidsize_1_material"/>
            <!-- Part tpu_arm_kidsize_telapak -->
            <geom type="mesh" class="collision" pos="2.60209e-17 -0.14 0.0728" quat="0.707107 0.707107 0 1.04478e-27" mesh="tpu_arm_kidsize_telapak" material="tpu_arm_kidsize_telapak_material"/>
            <!-- Part carbon_2mm_arm_kidsize_2 -->
            <geom type="mesh" class="collision" pos="2.94903e-17 8.32667e-17 0.043" quat="0.707107 -0 0.707107 8.07794e-28" mesh="carbon_2mm_arm_kidsize_2" material="carbon_2mm_arm_kidsize_2_material"/>
            <!-- Part right_lowerhand_parts -->
            <geom type="mesh" class="visual" pos="-0.00130389 -0.103918 0.0103596" quat="3.36358e-14 0.707107 0.707107 -2.59556e-14" mesh="right_lowerhand_visual" material="right_lowerhand_visual_material"/>
          </body>
        </body>
      </body>
      <!-- Link almi2_view_6_7__arm_bracket_2 -->
      <body name="almi2_view_6_7__arm_bracket_2" pos="0.0722867 -0.0191838 0.161307" quat="0.5 0.5 0.5 0.5">
        <!-- Joint from torso_kidsize25 to almi2_view_6_7__arm_bracket_2 -->
        <joint axis="0 0 1" name="left_shoulder_pitch" type="hinge" range="-3.141592653589793 3.141592653589793" frictionloss="0.1"/>
        <inertial pos="-1.00614e-16 -0.00223841 0.00829596" mass="0.0151289" fullinertia="2.57897e-06 5.57377e-06 5.85595e-06 -1.13759e-37 -2.36947e-36 4.04961e-07"/>
        <!-- Part almi2_view_6_7__arm_bracket_2 -->
        <geom type="mesh" class="collision" pos="0.0185 0.012 0.002" quat="0.707107 -0.707107 0 9.93174e-32" mesh="almi2_view_6_7__arm_bracket" material="almi2_view_6_7__arm_bracket_material"/>
        <!-- Part almi2_view_6_7__arm_bracket_2_parts -->
        <geom type="mesh" class="visual" pos="-1.04083e-16 -0.00223841 0.00829596" quat="0.5 -0.5 -0.5 -0.5" mesh="almi2_view_6_7__arm_bracket_2_visual" material="almi2_view_6_7__arm_bracket_2_visual_material"/>
        <!-- Link left_upperhand -->
        <body name="left_upperhand" pos="-0.0205 -0.0147498 0.0268034" quat="0 -0.707107 0 0.707107">
          <!-- Joint from almi2_view_6_7__arm_bracket_2 to left_upperhand -->
          <joint axis="0 0 1" name="left_shoulder_roll" type="hinge" range="-2.356194490192345 0.7853981633974483" frictionloss="0.1"/>
          <inertial pos="-0.0497057 -4.16564e-05 -0.0182021" mass="0.178" fullinertia="3.47766e-05 0.00029303 0.00029267 -7.35406e-07 1.52286e-05 1.94701e-08"/>
          <!-- Part mx_28_7 -->
          <geom type="mesh" class="collision" pos="-0.0341201 0.00818918 -0.0076946" quat="0.707107 4.20392e-14 -0.707107 4.20392e-14" mesh="mx_28" material="mx_28_material"/>
          <!-- Part almi2_view_13__14__arm_2 -->
          <geom type="mesh" class="collision" pos="-0.058605 -0.0819971 -0.0156" quat="4.27813e-17 -0.707107 -0.707107 9.04703e-17" mesh="almi2_view_13__14__arm" material="almi2_view_13__14__arm_material"/>
          <!-- Part mx_28_8 -->
          <geom type="mesh" class="collision" pos="-0.0653899 -0.0079054 -0.0287863" quat="0.5 -0.5 0.5 -0.5" mesh="mx_28" material="mx_28_material"/>
          <!-- Part left_upperhand_parts -->
          <geom type="mesh" class="visual" pos="-0.0497057 -4.16564e-05 -0.0182021" quat="7.83537e-14 -7.38732e-14 0.707107 -0.707107" mesh="left_upperhand_visual" material="left_upperhand_visual_material"/>
          <!-- Link left_lowerhand -->
          <body name="left_lowerhand" pos="-0.09951 -0.0205971 -0.0156" quat="0.5 0.5 -0.5 0.5">
            <!-- Joint from left_upperhand to left_lowerhand -->
            <joint axis="0 0 1" name="left_elbow" type="hinge" range="-2.356194490192345 2.356194490192345" frictionloss="0.1"/>
            <inertial pos="-0.00130389 0.103918 -0.0103596" mass="0.149258" fullinertia="0.000225269 5.61474e-05 0.000240431 7.02224e-06 1.20544e-07 -3.26703e-05"/>
            <!-- Part carbon_2mm_arm_kidsize_1_2 -->
            <geom type="mesh" class="collision" pos="-2.08167e-17 2.77556e-17 8.32667e-17" quat="0.5 -0.5 -0.5 -0.5" mesh="carbon_2mm_arm_kidsize_1" material="carbon_2mm_arm_kidsize_1_material"/>
            <!-- Part tpu_arm_kidsize_telapak_2 -->
            <geom type="mesh" class="collision" pos="5.89806e-17 0.14 -0.0728" quat="0.707107 -0.707107 3.33067e-16 -2.10981e-16" mesh="tpu_arm_kidsize_telapak" material="tpu_arm_kidsize_telapak_material"/>
            <!-- Part almi_4_5mm_connector_lower_arm_kidsize_2 -->
            <geom type="mesh" class="collision" pos="0.00225 0.0405 -5.55112e-17" quat="2.89486e-16 -2.10981e-16 -0.707107 0.707107" mesh="almi_4_5mm_connector_lower_arm_kidsize" material="almi_4_5mm_connector_lower_arm_kidsize_material"/>
            <!-- Part carbon_2mm_arm_kidsize_2_2 -->
            <geom type="mesh" class="collision" pos="-1.21431e-16 5.55112e-17 -0.043" quat="1.32477e-16 0.707107 -3.33067e-16 0.707107" mesh="carbon_2mm_arm_kidsize_2" material="carbon_2mm_arm_kidsize_2_material"/>
            <!-- Part left_lowerhand_parts -->
            <geom type="mesh" class="visual" pos="-0.00130389 0.103918 -0.0103596" quat="0.707107 3.03322e-14 -3.78586e-14 0.707107" mesh="left_lowerhand_visual" material="left_lowerhand_visual_material"/>
          </body>
        </body>
      </body>
      <!-- Link stainless_steel_2mm_upper_leg_bracket -->
      <body name="stainless_steel_2mm_upper_leg_bracket" pos="-0.0495 -0.0149172 0.0210065" quat="0.707107 -7.20722e-14 8.00471e-14 -0.707107">
        <!-- Joint from torso_kidsize25 to stainless_steel_2mm_upper_leg_bracket -->
        <joint axis="0 0 1" name="right_hip_yaw" type="hinge" range="-0.7853981633974483 1.5707963267948966" frictionloss="0.1"/>
        <inertial pos="-0.00421162 -1.80642e-07 -0.00839045" mass="0.0521561" fullinertia="1.13163e-05 2.97089e-05 2.98236e-05 -2.66522e-10 -2.03733e-07 3.66542e-11"/>
        <!-- Part stainless_steel_2mm_upper_leg_bracket -->
        <geom type="mesh" class="collision" pos="-0.03298 0.016 0" quat="0 1 0 0" mesh="stainless_steel_2mm_upper_leg_bracket" material="stainless_steel_2mm_upper_leg_bracket_material"/>
        <!-- Part stainless_steel_2mm_upper_leg_bracket_parts -->
        <geom type="mesh" class="visual" pos="-0.00421162 -1.80642e-07 -0.00839045" quat="0.707107 7.20722e-14 -8.00471e-14 0.707107" mesh="stainless_steel_2mm_upper_leg_bracket_visual" material="stainless_steel_2mm_upper_leg_bracket_visual_material"/>
        <!-- Link foot_right_1 -->
        <body name="foot_right_1" pos="-0.0335 3.55965e-14 -0.032" quat="0.5 0.5 0.5 0.5">
          <!-- Joint from stainless_steel_2mm_upper_leg_bracket to foot_right_1 -->
          <joint axis="0 0 1" name="right_hip_roll" type="hinge" range="-0.7853981633974483 1.5707963267948966" frictionloss="0.1"/>
          <inertial pos="-0.000121825 -0.0144674 0.00397654" mass="0.292396" fullinertia="0.000302471 0.00026243 0.000113113 -1.95767e-07 7.69534e-07 -1.25976e-05"/>
          <!-- Part mx_64t_2 -->
          <geom type="mesh" class="collision" pos="6.93889e-18 0 -0.0235" quat="1 0 0 0" mesh="mx_64t_2" material="mx_64t_2_material"/>
          <!-- Part almi_2mm_fr05_f101k_set -->
          <geom type="mesh" class="collision" pos="-1.38778e-17 -5.37764e-17 0.04958" quat="0.5 -0.5 -0.5 0.5" mesh="almi_2mm_fr05_f101k_set" material="almi_2mm_fr05_f101k_set_material"/>
          <!-- Part almi_2mm_connector_mx64 -->
          <geom type="mesh" class="collision" pos="-0.019 -0.043 0.01058" quat="0.707107 0 0 -0.707107" mesh="almi_2mm_connector_mx64" material="almi_2mm_connector_mx64_material"/>
          <!-- Part almi_2mm_connector_mx64_2 -->
          <geom type="mesh" class="collision" pos="0.019 -0.015 0.01058" quat="0.707107 -1.96262e-17 0 0.707107" mesh="almi_2mm_connector_mx64" material="almi_2mm_connector_mx64_material"/>
          <!-- Part fr05_f101k_set -->
          <geom type="mesh" class="collision" pos="-2.91434e-16 0 0.04938" quat="0.707107 -1.11022e-16 4.44089e-16 -0.707107" mesh="fr05_f101k_set" material="fr05_f101k_set_material"/>
          <!-- Part mx_64t_2_2 -->
          <geom type="mesh" class="collision" pos="1.38778e-17 -5.0307e-17 0.02558" quat="0.707107 3.92523e-17 0.707107 -0" mesh="mx_64t_2" material="mx_64t_2_material"/>
          <!-- Part mf128zz_1 -->
          <geom type="mesh" class="collision" pos="-2.77556e-16 -1.73472e-18 0.0516" quat="0.5 0.5 0.5 0.5" mesh="mf128zz_1" material="mf128zz_1_material"/>
          <!-- Part rx64_cap_1 -->
          <geom type="mesh" class="collision" pos="-2.56739e-16 1.04083e-17 0.05508" quat="0.707107 1.96262e-16 1.11022e-16 0.707107" mesh="rx64_cap_1" material="rx64_cap_1_material"/>
          <!-- Part hn05_i101_1 -->
          <geom type="mesh" class="collision" pos="-2.56739e-16 -1.56125e-17 0.05532" quat="0.5 0.5 0.5 0.5" mesh="hn05_i101_1" material="hn05_i101_1_material"/>
          <!-- Part rx64_cap_1_2 -->
          <geom type="mesh" class="collision" pos="-0.0232 -5.37764e-17 0.02558" quat="1.96262e-17 0.707107 -0 -0.707107" mesh="rx64_cap_1" material="rx64_cap_1_material"/>
          <!-- Part hn05_i101_1_2 -->
          <geom type="mesh" class="collision" pos="-0.02344 -4.85723e-17 0.02558" quat="0.5 -0.5 0.5 0.5" mesh="hn05_i101_1" material="hn05_i101_1_material"/>
          <!-- Part mf128zz_1_2 -->
          <geom type="mesh" class="collision" pos="-0.01972 -3.81639e-17 0.02558" quat="0.5 -0.5 0.5 0.5" mesh="mf128zz_1" material="mf128zz_1_material"/>
          <!-- Part foot_right_1_parts -->
          <geom type="mesh" class="visual" pos="-0.000121825 -0.0144674 0.00397654" quat="0.707107 -0.707107 -3.06422e-14 3.46806e-14" mesh="foot_right_1_visual" material="foot_right_1_visual_material"/>
          <!-- Link foot_right_2 -->
          <body name="foot_right_2" pos="0.0235 -4.68375e-17 0.02558" quat="8.46623e-15 0.707107 8.43769e-15 0.707107">
            <!-- Joint from foot_right_1 to foot_right_2 -->
            <joint axis="0 0 1" name="right_hip_pitch" type="hinge" range="-1.9634954084936207 1.1780972450961724" frictionloss="0.1"/>
            <inertial pos="0.00189202 0.0890217 -0.0236304" mass="0.273181" fullinertia="0.00054925 0.000131243 0.000472641 3.23355e-06 -6.73937e-08 8.86444e-07"/>
            <!-- Part stainless_steel_2mm__femur -->
            <geom type="mesh" class="collision" pos="-0.014 0.07746 -0.047" quat="0.707107 -0.707107 0 4.66121e-17" mesh="stainless_steel_2mm__femur" material="stainless_steel_2mm__femur_material"/>
            <!-- Part stainless_steel_2mm__femur_2 -->
            <geom type="mesh" class="collision" pos="-0.014 0.07746 0.003" quat="0.707107 -0.707107 -0 -3.08707e-32" mesh="stainless_steel_2mm__femur" material="stainless_steel_2mm__femur_material"/>
            <!-- Part almi_6_5mm_l_mx64 -->
            <geom type="mesh" class="collision" pos="-0.0134121 0.0859 -0.047" quat="1.32477e-16 -1.66533e-16 -0.707107 -0.707107" mesh="almi_6_5mm_l_mx64" material="almi_6_5mm_l_mx64_material"/>
            <!-- Part almi_6_5mm_l_mx64_2 -->
            <geom type="mesh" class="collision" pos="-0.0134121 0.0859 -0.0065" quat="4.85747e-16 0 -0.707107 -0.707107" mesh="almi_6_5mm_l_mx64" material="almi_6_5mm_l_mx64_material"/>
            <!-- Part mx_64t_1 -->
            <geom type="mesh" class="collision" pos="-6.45317e-16 0.134 -0.0235" quat="1 1.04083e-16 3.33067e-16 3.2613e-16" mesh="mx_64t_1" material="mx_64t_1_material"/>
            <!-- Part hn05_i101 -->
            <geom type="mesh" class="collision" pos="-5.91541e-16 0.134 -0.04694" quat="0.5 -0.5 -0.5 0.5" mesh="hn05_i101" material="hn05_i101_material"/>
            <!-- Part mf128zz -->
            <geom type="mesh" class="collision" pos="-6.13225e-16 0.134 -0.04322" quat="0.5 -0.5 -0.5 0.5" mesh="mf128zz" material="mf128zz_material"/>
            <!-- Part rx64_cap -->
            <geom type="mesh" class="collision" pos="-6.21031e-16 0.134 -0.0467" quat="3.28738e-16 -0.707107 -0.707107 1.81542e-16" mesh="rx64_cap" material="rx64_cap_material"/>
            <!-- Part foot_right_2_parts -->
            <geom type="mesh" class="visual" pos="0.00189202 0.0890217 -0.0236304" quat="0.5 0.5 -0.5 0.5" mesh="foot_right_2_visual" material="foot_right_2_visual_material"/>
            <!-- Link foot_right_3 -->
            <body name="foot_right_3" pos="-6.16694e-16 0.134 4.16334e-17" quat="1 1.38778e-16 3.33067e-16 7.66115e-15">
              <!-- Joint from foot_right_2 to foot_right_3 -->
              <joint axis="0 0 1" name="right_knee" type="hinge" range="-2.356194490192345 2.356194490192345" frictionloss="0.1"/>
              <inertial pos="0.00350206 0.0535427 -0.0235017" mass="0.157154" fullinertia="0.000266743 0.000115972 0.000200186 8.33375e-06 5.26492e-09 -6.48605e-09"/>
              <!-- Part stainless_steel_2mm_leg_spacer -->
              <geom type="mesh" class="collision" pos="0.024 0.0190814 -0.045" quat="0.707107 8.679e-17 -1.11022e-16 0.707107" mesh="stainless_steel_2mm_leg_spacer" material="stainless_steel_2mm_leg_spacer_material"/>
              <!-- Part stainless_steel_2mm_shinebone -->
              <geom type="mesh" class="collision" pos="0.0135 0.0197269 -0.05" quat="0.707107 0.707107 3.33067e-16 -8.58644e-17" mesh="stainless_steel_2mm_shinebone" material="stainless_steel_2mm_shinebone_material"/>
              <!-- Part stainless_steel_2mm_shinebone_2 -->
              <geom type="mesh" class="collision" pos="0.0135 0.0197269 0" quat="0.707107 0.707107 0 -1.30756e-31" mesh="stainless_steel_2mm_shinebone" material="stainless_steel_2mm_shinebone_material"/>
              <!-- Part foot_right_3_parts -->
              <geom type="mesh" class="visual" pos="0.00350206 0.0535427 -0.0235017" quat="0.5 0.5 -0.5 0.5" mesh="foot_right_3_visual" material="foot_right_3_visual_material"/>
              <!-- Link foot_right_4 -->
              <body name="foot_right_4" pos="-1.10155e-16 0.111702 2.08167e-17" quat="1 0 2.22045e-16 -3.1572e-14">
                <!-- Joint from foot_right_3 to foot_right_4 -->
                <joint axis="0 0 1" name="right_ankle_pitch" type="hinge" range="-1.5707963267948966 1.5707963267948966" frictionloss="0.1"/>
                <inertial pos="-0.0215978 -0.0144558 -0.0236219" mass="0.292143" fullinertia="0.000112946 0.000262476 0.000302507 -1.25976e-05 7.69336e-07 -2.05088e-07"/>
                <!-- Part mx_64t_3 -->
                <geom type="mesh" class="collision" pos="-0.04908 0 -0.0235" quat="0.707107 1.69407e-21 0.707107 -0" mesh="mx_64t_3" material="mx_64t_3_material"/>
                <!-- Part fr05_f101k_set_1 -->
                <geom type="mesh" class="collision" pos="0.024 -4.58208e-05 -0.0235" quat="0.5 -0.5 0.5 -0.5" mesh="fr05_f101k_set_1" material="fr05_f101k_set_1_material"/>
                <!-- Part almi_2mm_connector_mx64_1 -->
                <geom type="mesh" class="collision" pos="-0.015 -0.015 -0.0425" quat="0.5 0.5 0.5 0.5" mesh="almi_2mm_connector_mx64_1" material="almi_2mm_connector_mx64_1_material"/>
                <!-- Part almi_2mm_connector_mx64_1_2 -->
                <geom type="mesh" class="collision" pos="-0.015 -0.043 -0.0045" quat="0.5 -0.5 0.5 -0.5" mesh="almi_2mm_connector_mx64_1" material="almi_2mm_connector_mx64_1_material"/>
                <!-- Part mx_64t_3_2 -->
                <geom type="mesh" class="collision" pos="0 0 -0.0235" quat="1 0 -2.22045e-16 -0" mesh="mx_64t_3" material="mx_64t_3_material"/>
                <!-- Part almi_2mm_fr05_f101k_set_1 -->
                <geom type="mesh" class="collision" pos="0.024 0 -0.0235" quat="0.707107 -1.90211e-16 1.11022e-16 0.707107" mesh="almi_2mm_fr05_f101k_set_1" material="almi_2mm_fr05_f101k_set_1_material"/>
                <!-- Part hn05_i101_2 -->
                <geom type="mesh" class="collision" pos="4.25007e-17 0 -0.04694" quat="0.707107 -0.707107 1.11022e-16 1.30023e-16" mesh="hn05_i101_2" material="hn05_i101_2_material"/>
                <!-- Part mf128zz_2 -->
                <geom type="mesh" class="collision" pos="1.82146e-17 -5.55112e-17 -0.04322" quat="0.707107 -0.707107 -0 1.37383e-16" mesh="mf128zz_2" material="mf128zz_2_material"/>
                <!-- Part rx64_cap_2 -->
                <geom type="mesh" class="collision" pos="1.38778e-17 -5.55112e-17 -0.0467" quat="1.50228e-29 -1 3.46945e-17 1.17961e-16" mesh="rx64_cap_2" material="rx64_cap_2_material"/>
                <!-- Part mf128zz_2_2 -->
                <geom type="mesh" class="collision" pos="0.02622 -4.58208e-05 -0.0235" quat="0.707107 7.6595e-17 -3.33067e-16 -0.707107" mesh="mf128zz_2" material="mf128zz_2_material"/>
                <!-- Part hn05_i101_2_2 -->
                <geom type="mesh" class="collision" pos="0.02994 -4.58208e-05 -0.0235" quat="0.707107 7.85046e-17 0 -0.707107" mesh="hn05_i101_2" material="hn05_i101_2_material"/>
                <!-- Part rx64_cap_2_2 -->
                <geom type="mesh" class="collision" pos="0.0297 -4.58208e-05 -0.0235" quat="0.5 -0.5 0.5 -0.5" mesh="rx64_cap_2" material="rx64_cap_2_material"/>
                <!-- Part foot_right_4_parts -->
                <geom type="mesh" class="visual" pos="-0.0215978 -0.0144558 -0.0236219" quat="0.5 0.5 -0.5 0.5" mesh="foot_right_4_visual" material="foot_right_4_visual_material"/>
                <!-- Link foot_right_5 -->
                <body name="foot_right_5" pos="-0.02558 4.44089e-15 -0.0235" quat="1.79015e-14 0.707107 1.94289e-14 0.707107">
                  <!-- Joint from foot_right_4 to foot_right_5 -->
                  <joint axis="0 0 1" name="right_ankle_roll" type="hinge" range="-1.0471975512 1.0471975512" frictionloss="0.1"/>
                  <inertial pos="-0.00431494 -0.027932 0.0410276" mass="0.132192" fullinertia="0.000177533 0.000221544 6.06598e-05 -1.91248e-06 5.63401e-06 8.6074e-07"/>
                  <!-- Part pla_50__shoes -->
                  <geom type="mesh" class="collision" pos="-0.04925 -0.032 0.10376" quat="0.707107 1.6263e-19 -0.707107 -2.22045e-16" mesh="pla_50__shoes" material="pla_50__shoes_material"/>
                  <!-- Part almi_2mm_lower_leg -->
                  <geom type="mesh" class="collision" pos="-0.00775 -0.032 0.02876" quat="7.92724e-17 -0.707107 1.11022e-16 0.707107" mesh="almi_2mm_lower_leg" material="almi_2mm_lower_leg_material"/>
                  <!-- Part stainless_steel_2mm_lower_leg_bracket -->
                  <geom type="mesh" class="collision" pos="-0.016 -0.032 0.00052" quat="0.5 -0.5 -0.5 -0.5" mesh="stainless_steel_2mm_lower_leg_bracket" material="stainless_steel_2mm_lower_leg_bracket_material"/>
                  <!-- Part foot_right_5_parts -->
                  <geom type="mesh" class="visual" pos="-0.00431494 -0.027932 0.0410276" quat="0.707107 -0.707107 -4.88498e-14 5.3521e-14" mesh="foot_right_5_visual" material="foot_right_5_visual_material"/>
                </body>
              </body>
            </body>
          </body>
        </body>
      </body>
      <!-- Link stainless_steel_2mm_upper_leg_bracket_mir -->
      <body name="stainless_steel_2mm_upper_leg_bracket_mir" pos="0.0495 -0.0149156 0.0210065" quat="0.707107 -7.20327e-14 8.02691e-14 -0.707107">
        <!-- Joint from torso_kidsize25 to stainless_steel_2mm_upper_leg_bracket_mir -->
        <joint axis="0 0 1" name="left_hip_yaw" type="hinge" range="-1.5707963267948966 0.7853981633974483" frictionloss="0.1"/>
        <inertial pos="-0.00421162 1.80642e-07 -0.00839045" mass="0.0521561" fullinertia="1.13163e-05 2.97089e-05 2.98236e-05 2.66522e-10 -2.03733e-07 -3.66542e-11"/>
        <!-- Part stainless_steel_2mm_upper_leg_bracket_mir -->
        <geom type="mesh" class="collision" pos="-0.03298 -0.016 0" quat="1 0 0 0" mesh="stainless_steel_2mm_upper_leg_bracket_mir" material="stainless_steel_2mm_upper_leg_bracket_mir_material"/>
        <!-- Part stainless_steel_2mm_upper_leg_bracket_mir_parts -->
        <geom type="mesh" class="visual" pos="-0.00421162 1.80642e-07 -0.00839045" quat="0.707107 7.20329e-14 -8.01581e-14 0.707107" mesh="stainless_steel_2mm_upper_leg_bracket_mir_visual" material="stainless_steel_2mm_upper_leg_bracket_mir_visual_material"/>
        <!-- Link foot_left_1 -->
        <body name="foot_left_1" pos="-0.0335 -3.56451e-14 -0.032" quat="0.5 -0.5 0.5 -0.5">
          <!-- Joint from stainless_steel_2mm_upper_leg_bracket_mir to foot_left_1 -->
          <joint axis="0 0 1" name="left_hip_roll" type="hinge" range="-1.5707963267948966 0.7853981633974483" frictionloss="0.1"/>
          <inertial pos="-0.000121924 0.0144559 0.00398223" mass="0.292143" fullinertia="0.000302507 0.000262475 0.000112946 1.96526e-07 7.69256e-07 1.25975e-05"/>
          <!-- Part mx_64t_mir_1 -->
          <geom type="mesh" class="collision" pos="0 0 -0.0235" quat="0 1 0 0" mesh="mx_64t_mir_1" material="mx_64t_mir_1_material"/>
          <!-- Part almi_2mm_fr05_f101k_set_mir -->
          <geom type="mesh" class="collision" pos="3.46945e-17 -3.1225e-17 0.04958" quat="0.5 -0.5 0.5 -0.5" mesh="almi_2mm_fr05_f101k_set_mir" material="almi_2mm_fr05_f101k_set_mir_material"/>
          <!-- Part almi_2mm_connector_mx64_mir -->
          <geom type="mesh" class="collision" pos="-0.019 0.043 0.01058" quat="3.92523e-17 0.707107 0.707107 -5.87371e-28" mesh="almi_2mm_connector_mx64_mir" material="almi_2mm_connector_mx64_mir_material"/>
          <!-- Part fr05_f101k_set_mir -->
          <geom type="mesh" class="collision" pos="-2.15106e-16 4.58208e-05 0.04958" quat="1.30154e-16 0.707107 0.707107 1.09524e-16" mesh="fr05_f101k_set_mir" material="fr05_f101k_set_mir_material"/>
          <!-- Part almi_2mm_connector_mx64_mir_2 -->
          <geom type="mesh" class="collision" pos="0.019 0.015 0.01058" quat="9.54067e-28 0.707107 -0.707107 7.85046e-17" mesh="almi_2mm_connector_mx64_mir" material="almi_2mm_connector_mx64_mir_material"/>
          <!-- Part mx_64t_mir_1_2 -->
          <geom type="mesh" class="collision" pos="2.77556e-17 -3.29597e-17 0.02558" quat="4.95655e-17 0.707107 -1.11022e-16 -0.707107" mesh="mx_64t_mir_1" material="mx_64t_mir_1_material"/>
          <!-- Part mf128zz_mir_1 -->
          <geom type="mesh" class="collision" pos="-2.28983e-16 4.58208e-05 0.0518" quat="0.5 0.5 -0.5 -0.5" mesh="mf128zz_mir_1" material="mf128zz_mir_1_material"/>
          <!-- Part hn05_i101_mir_1 -->
          <geom type="mesh" class="collision" pos="-2.22045e-16 4.58208e-05 0.05552" quat="0.5 0.5 -0.5 -0.5" mesh="hn05_i101_mir_1" material="hn05_i101_mir_1_material"/>
          <!-- Part rx64_cap_mir_1 -->
          <geom type="mesh" class="collision" pos="-2.22045e-16 4.58208e-05 0.05528" quat="3.92523e-17 -0.707107 0.707107 -7.85046e-17" mesh="rx64_cap_mir_1" material="rx64_cap_mir_1_material"/>
          <!-- Part rx64_cap_mir_1_2 -->
          <geom type="mesh" class="collision" pos="-0.0232 1.73472e-18 0.02558" quat="0.5 0.5 0.5 0.5" mesh="rx64_cap_mir_1" material="rx64_cap_mir_1_material"/>
          <!-- Part hn05_i101_mir_1_2 -->
          <geom type="mesh" class="collision" pos="-0.02344 8.67362e-18 0.02558" quat="0.707107 -3.92523e-17 -0 0.707107" mesh="hn05_i101_mir_1" material="hn05_i101_mir_1_material"/>
          <!-- Part mf128zz_mir_1_2 -->
          <geom type="mesh" class="collision" pos="-0.01972 1.9082e-17 0.02558" quat="0.707107 -3.92523e-17 -1.11022e-16 0.707107" mesh="mf128zz_mir_1" material="mf128zz_mir_1_material"/>
          <!-- Part foot_left_1_parts -->
          <geom type="mesh" class="visual" pos="-0.000121924 0.0144559 0.00398223" quat="3.19231e-14 -2.78649e-14 0.707107 -0.707107" mesh="foot_left_1_visual" material="foot_left_1_visual_material"/>
          <!-- Link foot_left_2 -->
          <body name="foot_left_2" pos="0.0235 2.60209e-17 0.02558" quat="0.707107 4.77049e-16 -0.707107 -5.96745e-16">
            <!-- Joint from foot_left_1 to foot_left_2 -->
            <joint axis="0 0 1" name="left_hip_pitch" type="hinge" range="-1.9634954084936207 1.1780972450961724" frictionloss="0.1"/>
            <inertial pos="0.00189202 0.0890217 0.0236304" mass="0.273181" fullinertia="0.00054925 0.000131243 0.000472641 3.23354e-06 6.73963e-08 -8.86436e-07"/>
            <!-- Part mx_64t_mir -->
            <geom type="mesh" class="collision" pos="-6.32307e-16 0.134 0.0235" quat="1 0 0 -7.80626e-17" mesh="mx_64t_mir" material="mx_64t_mir_material"/>
            <!-- Part stainless_steel_2mm__femur_mir -->
            <geom type="mesh" class="collision" pos="-0.014 0.07746 0.047" quat="0.707107 0.707107 0 -3.48437e-29" mesh="stainless_steel_2mm__femur_mir" material="stainless_steel_2mm__femur_mir_material"/>
            <!-- Part stainless_steel_2mm__femur_mir_2 -->
            <geom type="mesh" class="collision" pos="-0.014 0.07746 -0.003" quat="0.707107 0.707107 -0 1.93407e-32" mesh="stainless_steel_2mm__femur_mir" material="stainless_steel_2mm__femur_mir_material"/>
            <!-- Part almi_6_5mm_l_mx64_mir -->
            <geom type="mesh" class="collision" pos="-0.0134121 0.0859 0.0065" quat="1.2809e-30 0 -0.707107 0.707107" mesh="almi_6_5mm_l_mx64_mir" material="almi_6_5mm_l_mx64_mir_material"/>
            <!-- Part almi_6_5mm_l_mx64_mir_2 -->
            <geom type="mesh" class="collision" pos="-0.0134121 0.0859 0.047" quat="3.34314e-29 -0 -0.707107 0.707107" mesh="almi_6_5mm_l_mx64_mir" material="almi_6_5mm_l_mx64_mir_material"/>
            <!-- Part hn05_i101_mir -->
            <geom type="mesh" class="collision" pos="-6.54858e-16 0.134 0.04694" quat="0.5 0.5 0.5 0.5" mesh="hn05_i101_mir" material="hn05_i101_mir_material"/>
            <!-- Part rx64_cap_mir -->
            <geom type="mesh" class="collision" pos="-6.21898e-16 0.134 0.0467" quat="3.82868e-17 0.707107 0.707107 -1.10957e-16" mesh="rx64_cap_mir" material="rx64_cap_mir_material"/>
            <!-- Part mf128zz_mir -->
            <geom type="mesh" class="collision" pos="-6.34041e-16 0.134 0.04322" quat="0.5 0.5 0.5 0.5" mesh="mf128zz_mir" material="mf128zz_mir_material"/>
            <!-- Part foot_left_2_parts -->
            <geom type="mesh" class="visual" pos="0.00189202 0.0890217 0.0236304" quat="0.5 0.5 -0.5 0.5" mesh="foot_left_2_visual" material="foot_left_2_visual_material"/>
            <!-- Link foot_left_3 -->
            <body name="foot_left_3" pos="-6.42715e-16 0.134 -4.16334e-17" quat="1 -0 -0 2.9319e-15">
              <!-- Joint from foot_left_2 to foot_left_3 -->
              <joint axis="0 0 1" name="left_knee" type="hinge" range="-2.356194490192345 2.356194490192345" frictionloss="0.1"/>
              <inertial pos="0.00350206 0.0535427 0.0235017" mass="0.157154" fullinertia="0.000266743 0.000115972 0.000200186 8.33375e-06 -5.26492e-09 6.48605e-09"/>
              <!-- Part stainless_steel_2mm_shinebone_mir -->
              <geom type="mesh" class="collision" pos="0.0135 0.0197269 0.05" quat="0.707107 -0.707107 1.11022e-16 1.57009e-16" mesh="stainless_steel_2mm_shinebone_mir" material="stainless_steel_2mm_shinebone_mir_material"/>
              <!-- Part stainless_steel_2mm_leg_spacer_mir -->
              <geom type="mesh" class="collision" pos="0.024 0.0190814 0.045" quat="0.707107 -3.92523e-17 -0 0.707107" mesh="stainless_steel_2mm_leg_spacer_mir" material="stainless_steel_2mm_leg_spacer_mir_material"/>
              <!-- Part stainless_steel_2mm_shinebone_mir_2 -->
              <geom type="mesh" class="collision" pos="0.0135 0.0197269 0" quat="0.707107 -0.707107 0 1.24399e-31" mesh="stainless_steel_2mm_shinebone_mir" material="stainless_steel_2mm_shinebone_mir_material"/>
              <!-- Part foot_left_3_parts -->
              <geom type="mesh" class="visual" pos="0.00350206 0.0535427 0.0235017" quat="0.5 0.5 -0.5 0.5" mesh="foot_left_3_visual" material="foot_left_3_visual_material"/>
              <!-- Link foot_left_4 -->
              <body name="foot_left_4" pos="-8.67362e-17 0.111702 6.59195e-17" quat="1 0 -5.55112e-17 6.0531e-16">
                <!-- Joint from foot_left_3 to foot_left_4 -->
                <joint axis="0 0 1" name="left_ankle_pitch" type="hinge" range="-1.5707963267948966 1.5707963267948966" frictionloss="0.1"/>
                <inertial pos="-0.0215978 -0.0144559 0.0236219" mass="0.292143" fullinertia="0.000112946 0.000262475 0.000302507 -1.25975e-05 -7.69402e-07 2.05066e-07"/>
                <!-- Part mx_64t_mir_2 -->
                <geom type="mesh" class="collision" pos="-0.04908 0 0.0235" quat="0.707107 0 -0.707107 -5.55112e-17" mesh="mx_64t_mir_2" material="mx_64t_mir_2_material"/>
                <!-- Part almi_2mm_connector_mx64_mir_1 -->
                <geom type="mesh" class="collision" pos="-0.015 -0.015 0.0425" quat="0.5 -0.5 -0.5 0.5" mesh="almi_2mm_connector_mx64_mir_1" material="almi_2mm_connector_mx64_mir_1_material"/>
                <!-- Part fr05_f101k_set_mir_1 -->
                <geom type="mesh" class="collision" pos="0.024 -4.58208e-05 0.0235" quat="0.5 0.5 -0.5 -0.5" mesh="fr05_f101k_set_mir_1" material="fr05_f101k_set_mir_1_material"/>
                <!-- Part mx_64t_mir_2_2 -->
                <geom type="mesh" class="collision" pos="0 0 0.0235" quat="1 -0 -1.11022e-16 6.93889e-18" mesh="mx_64t_mir_2" material="mx_64t_mir_2_material"/>
                <!-- Part almi_2mm_fr05_f101k_set_mir_1 -->
                <geom type="mesh" class="collision" pos="0.024 5.55112e-17 0.0235" quat="0.707107 -0 -1.41499e-16 0.707107" mesh="almi_2mm_fr05_f101k_set_mir_1" material="almi_2mm_fr05_f101k_set_mir_1_material"/>
                <!-- Part almi_2mm_connector_mx64_mir_1_2 -->
                <geom type="mesh" class="collision" pos="-0.015 -0.043 0.0045" quat="0.5 0.5 -0.5 -0.5" mesh="almi_2mm_connector_mx64_mir_1" material="almi_2mm_connector_mx64_mir_1_material"/>
                <!-- Part hn05_i101_mir_2 -->
                <geom type="mesh" class="collision" pos="5.20417e-18 0 0.04694" quat="0.707107 0.707107 -0 1.88176e-30" mesh="hn05_i101_mir_2" material="hn05_i101_mir_2_material"/>
                <!-- Part mf128zz_mir_2 -->
                <geom type="mesh" class="collision" pos="2.60209e-17 0 0.04322" quat="0.707107 0.707107 -0 1.60286e-30" mesh="mf128zz_mir_2" material="mf128zz_mir_2_material"/>
                <!-- Part rx64_cap_mir_2 -->
                <geom type="mesh" class="collision" pos="1.04083e-17 0 0.0467" quat="0 1 0 0" mesh="rx64_cap_mir_2" material="rx64_cap_mir_2_material"/>
                <!-- Part mf128zz_mir_2_2 -->
                <geom type="mesh" class="collision" pos="0.02622 -4.58208e-05 0.0235" quat="0.707107 9.05547e-17 -1.11022e-16 -0.707107" mesh="mf128zz_mir_2" material="mf128zz_mir_2_material"/>
                <!-- Part hn05_i101_mir_2_2 -->
                <geom type="mesh" class="collision" pos="0.02994 -4.58208e-05 0.0235" quat="0.707107 1.57009e-16 -1.11022e-16 -0.707107" mesh="hn05_i101_mir_2" material="hn05_i101_mir_2_material"/>
                <!-- Part rx64_cap_mir_2_2 -->
                <geom type="mesh" class="collision" pos="0.0297 -4.58208e-05 0.0235" quat="0.5 0.5 -0.5 -0.5" mesh="rx64_cap_mir_2" material="rx64_cap_mir_2_material"/>
                <!-- Part foot_left_4_parts -->
                <geom type="mesh" class="visual" pos="-0.0215978 -0.0144559 0.0236219" quat="0.5 0.5 -0.5 0.5" mesh="foot_left_4_visual" material="foot_left_4_visual_material"/>
                <!-- Link foot_left_5 -->
                <body name="foot_left_5" pos="-0.02558 0 0.0235" quat="0.707107 -1.6845e-14 0.707107 -1.68437e-14">
                  <!-- Joint from foot_left_4 to foot_left_5 -->
                  <joint axis="0 0 1" name="left_ankle_roll" type="hinge" range="-1.0471975512 1.0471975512" frictionloss="0.1"/>
                  <inertial pos="-0.00577513 0.0300863 0.0389132" mass="0.229936" fullinertia="0.000336096 0.000437543 0.000121048 2.89074e-06 4.67383e-06 5.55837e-07"/>
                  <!-- Part almi_2mm_lower_leg_mir -->
                  <geom type="mesh" class="collision" pos="-0.00775 0.032 0.02876" quat="0.707107 -1.66455e-16 0.707107 -1.11022e-16" mesh="almi_2mm_lower_leg_mir" material="almi_2mm_lower_leg_mir_material"/>
                  <!-- Part stainless_steel_2mm_lower_leg_bracket_mir -->
                  <geom type="mesh" class="collision" pos="-0.016 0.032 0.00052" quat="0.5 -0.5 -0.5 -0.5" mesh="stainless_steel_2mm_lower_leg_bracket_mir" material="stainless_steel_2mm_lower_leg_bracket_mir_material"/>
                  <!-- Part pla_50__shoes_mir -->
                  <geom type="mesh" class="collision" pos="-0.04925 0.032 0.10376" quat="8.92494e-30 -0.707107 -0 -0.707107" mesh="pla_50__shoes_mir" material="pla_50__shoes_mir_material"/>
                  <!-- Part foot_left_5_parts -->
                  <geom type="mesh" class="visual" pos="-0.00577513 0.0300863 0.0389132" quat="4.88073e-14 -4.47872e-14 0.707107 -0.707107" mesh="foot_left_5_visual" material="foot_left_5_visual_material"/>
                </body>
              </body>
            </body>
          </body>
        </body>
      </body>
    </body>
  </worldbody>
  <asset>
    <mesh file="petg_2mm_headbracket_old.stl"/>
    <mesh file="bracket_back_bumper_mir.stl"/>
    <mesh file="merged/foot_left_3_visual.stl"/>
    <mesh file="mf128zz_mir_2.stl"/>
    <mesh file="rx64_cap_2.stl"/>
    <mesh file="mx_64t_3.stl"/>
    <mesh file="stainless_steel_2mm_lower_leg_bracket_mir.stl"/>
    <mesh file="rx64_cap_1.stl"/>
    <mesh file="hn05_i101_mir_2.stl"/>
    <mesh file="fr05_f101k_set_mir.stl"/>
    <mesh file="holder_lower_bracket_mir.stl"/>
    <mesh file="spacer_106_64_mir2_mir.stl"/>
    <mesh file="almi_5mm_bracket_servo_1_2.stl"/>
    <mesh file="fr05_f101k_set.stl"/>
    <mesh file="merged/foot_left_4_visual.stl"/>
    <mesh file="almi_2mm_fr05_f101k_set_mir.stl"/>
    <mesh file="front_upper_bumper_mir.stl"/>
    <mesh file="almi_2mm_lower_leg_mir.stl"/>
    <mesh file="stainless_steel_2mm_upper_leg_bracket.stl"/>
    <mesh file="almi_6_5mm_l_mx64.stl"/>
    <mesh file="mf128zz_2.stl"/>
    <mesh file="merged/right_upperhand_visual.stl"/>
    <mesh file="hn05_i101_mir.stl"/>
    <mesh file="merged/left_upperhand_visual.stl"/>
    <mesh file="spacer_106_64_mir2.stl"/>
    <mesh file="merged/foot_left_2_visual.stl"/>
    <mesh file="almi_2mm_connector_mx64.stl"/>
    <mesh file="camera_frame.stl"/>
    <mesh file="almi_2mm_connector_mx64_mir.stl"/>
    <mesh file="mx_64t.stl"/>
    <mesh file="fr05_f101k_set_1.stl"/>
    <mesh file="rx64_cap.stl"/>
    <mesh file="stainless_steel_2mm_shinebone_mir.stl"/>
    <mesh file="almi_4mm_neck_bracket.stl"/>
    <mesh file="mf128zz_mir_1.stl"/>
    <mesh file="stainless_steel_2mm_lower_leg_bracket.stl"/>
    <mesh file="mx_64t_mir.stl"/>
    <mesh file="handler_holder_siber.stl"/>
    <mesh file="merged/foot_right_2_visual.stl"/>
    <mesh file="merged/torso_kidsize25_visual.stl"/>
    <mesh file="merged/foot_right_4_visual.stl"/>
    <mesh file="almi_2mm_fr05_f101k_set_mir_1.stl"/>
    <mesh file="carbon_2mm_arm_kidsize_1.stl"/>
    <mesh file="front_pillar.stl"/>
    <mesh file="almi_2mm_floor_2nd__1.stl"/>
    <mesh file="mf128zz_mir.stl"/>
    <mesh file="merged/neck_visual.stl"/>
    <mesh file="almi_6_5mm_l_mx64_mir.stl"/>
    <mesh file="front_upper_bumper.stl"/>
    <mesh file="tpu_arm_kidsize_telapak.stl"/>
    <mesh file="bracket_back_bumper.stl"/>
    <mesh file="stainless_steel_2mm_leg_spacer_mir.stl"/>
    <mesh file="petg_2mm_rotatingheadbracket.stl"/>
    <mesh file="merged/left_lowerhand_visual.stl"/>
    <mesh file="bumper_front_lower_mir.stl"/>
    <mesh file="mf128zz.stl"/>
    <mesh file="hn05_i101_1.stl"/>
    <mesh file="petg_5_19_mx28_seating.stl"/>
    <mesh file="upper_floor.stl"/>
    <mesh file="spacer_bracket_id_1_19_2.stl"/>
    <mesh file="bumper_front_lower.stl"/>
    <mesh file="2nd_floor.stl"/>
    <mesh file="merged/right_lowerhand_visual.stl"/>
    <mesh file="almi_2mm_fr05_f101k_set_1.stl"/>
    <mesh file="almi2_view_6_7__arm_bracket.stl"/>
    <mesh file="mx_64t_1.stl"/>
    <mesh file="bracket_1_2_lower_left.stl"/>
    <mesh file="camera_logitech_c920_offset_2mm.stl"/>
    <mesh file="almi_2mm_lower_leg.stl"/>
    <mesh file="stainless_steel_2mm__femur_mir.stl"/>
    <mesh file="mx_64t_mir_2.stl"/>
    <mesh file="fr05_f101k_set_mir_1.stl"/>
    <mesh file="merged/foot_left_5_visual.stl"/>
    <mesh file="merged/foot_left_1_visual.stl"/>
    <mesh file="handle_bracket_kidsize.stl"/>
    <mesh file="pla_50__shoes.stl"/>
    <mesh file="mf128zz_1.stl"/>
    <mesh file="merged/stainless_steel_2mm_upper_leg_bracket_mir_visual.stl"/>
    <mesh file="stainless_steel_2mm_upper_leg_bracket_mir.stl"/>
    <mesh file="merged/foot_right_5_visual.stl"/>
    <mesh file="merged/almi2_view_6_7__arm_bracket_2_visual.stl"/>
    <mesh file="carbon_2mm_arm_kidsize_2.stl"/>
    <mesh file="almi_2mm_connector_mx64_1.stl"/>
    <mesh file="merged/foot_right_3_visual.stl"/>
    <mesh file="carbon_2mm_neck_side_plate.stl"/>
    <mesh file="stainless_steel_2mm_shinebone.stl"/>
    <mesh file="merged/almi2_view_6_7__arm_bracket_visual.stl"/>
    <mesh file="almi_5mm_bracket_servo_1_2_left.stl"/>
    <mesh file="mx_64t_2.stl"/>
    <mesh file="mx_64t_mir_1.stl"/>
    <mesh file="hn05_i101_mir_1.stl"/>
    <mesh file="stainless_steel_2mm__femur.stl"/>
    <mesh file="merged/head_visual.stl"/>
    <mesh file="merged/foot_right_1_visual.stl"/>
    <mesh file="holder_bumper_upper.stl"/>
    <mesh file="hn05_i101.stl"/>
    <mesh file="mx_64t_mir1.stl"/>
    <mesh file="spacer_bracket_id_1_19_2_mir.stl"/>
    <mesh file="back_bumper.stl"/>
    <mesh file="pla_50__shoes_mir.stl"/>
    <mesh file="bracket_1_2_lower.stl"/>
    <mesh file="almi_4_5mm_connector_lower_arm_kidsize.stl"/>
    <mesh file="almi_2mm_fr05_f101k_set.stl"/>
    <mesh file="battery_holder.stl"/>
    <mesh file="rx64_cap_mir_1.stl"/>
    <mesh file="rx64_cap_mir_2.stl"/>
    <mesh file="hn05_i101_2.stl"/>
    <mesh file="pcnel_exch.stl"/>
    <mesh file="almi_2mm_connector_mx64_mir_1.stl"/>
    <mesh file="stainless_steel_2mm_leg_spacer.stl"/>
    <mesh file="handle.stl"/>
    <mesh file="mx_28.stl"/>
    <mesh file="holder_lower_bracket.stl"/>
    <mesh file="almi2_view_13__14__arm.stl"/>
    <mesh file="merged/stainless_steel_2mm_upper_leg_bracket_visual.stl"/>
    <mesh file="rx64_cap_mir.stl"/>
    <mesh file="xt_bracket.stl"/>
    <material name="mx_64t_mir1_material" rgba="0.55972 0.560028 0.558638 1"/>
    <material name="mx_64t_material" rgba="0.55972 0.560028 0.558638 1"/>
    <material name="mx_28_material" rgba="0.55972 0.560028 0.558638 1"/>
    <material name="upper_floor_material" rgba="0.55972 0.560028 0.558638 1"/>
    <material name="2nd_floor_material" rgba="0.55972 0.560028 0.558638 1"/>
    <material name="front_pillar_material" rgba="0.55972 0.560028 0.558638 1"/>
    <material name="pcnel_exch_material" rgba="0.55972 0.560028 0.558638 1"/>
    <material name="spacer_bracket_id_1_19_2_mir_material" rgba="0.55972 0.560028 0.558638 1"/>
    <material name="handle_bracket_kidsize_material" rgba="0.55972 0.560028 0.558638 1"/>
    <material name="almi_5mm_bracket_servo_1_2_left_material" rgba="0.55972 0.560028 0.558638 1"/>
    <material name="handle_material" rgba="0.55972 0.560028 0.558638 1"/>
    <material name="holder_bumper_upper_material" rgba="0.55972 0.560028 0.558638 1"/>
    <material name="handler_holder_siber_material" rgba="0.55972 0.560028 0.558638 1"/>
    <material name="bracket_1_2_lower_left_material" rgba="0.55972 0.560028 0.558638 1"/>
    <material name="front_upper_bumper_material" rgba="0.55972 0.560028 0.558638 1"/>
    <material name="petg_5_19_mx28_seating_material" rgba="0.55972 0.560028 0.558638 1"/>
    <material name="almi_5mm_bracket_servo_1_2_material" rgba="0.55972 0.560028 0.558638 1"/>
    <material name="spacer_bracket_id_1_19_2_material" rgba="0.55972 0.560028 0.558638 1"/>
    <material name="front_upper_bumper_mir_material" rgba="0.55972 0.560028 0.558638 1"/>
    <material name="bracket_1_2_lower_material" rgba="0.55972 0.560028 0.558638 1"/>
    <material name="bumper_front_lower_mir_material" rgba="0.55972 0.560028 0.558638 1"/>
    <material name="spacer_106_64_mir2_material" rgba="0.55972 0.560028 0.558638 1"/>
    <material name="holder_lower_bracket_mir_material" rgba="0.55972 0.560028 0.558638 1"/>
    <material name="almi_2mm_floor_2nd__1_material" rgba="0.55972 0.560028 0.558638 1"/>
    <material name="spacer_106_64_mir2_mir_material" rgba="0.55972 0.560028 0.558638 1"/>
    <material name="back_bumper_material" rgba="0.55972 0.560028 0.558638 1"/>
    <material name="xt_bracket_material" rgba="0.55972 0.560028 0.558638 1"/>
    <material name="battery_holder_material" rgba="0.55972 0.560028 0.558638 1"/>
    <material name="bracket_back_bumper_material" rgba="0.55972 0.560028 0.558638 1"/>
    <material name="holder_lower_bracket_material" rgba="0.55972 0.560028 0.558638 1"/>
    <material name="bumper_front_lower_material" rgba="0.55972 0.560028 0.558638 1"/>
    <material name="bracket_back_bumper_mir_material" rgba="0.55972 0.560028 0.558638 1"/>
    <material name="torso_kidsize25_visual_material" rgba="0.55972 0.560028 0.558638 1"/>
    <material name="almi_4mm_neck_bracket_material" rgba="0.55972 0.560028 0.558638 1"/>
    <material name="carbon_2mm_neck_side_plate_material" rgba="0.55972 0.560028 0.558638 1"/>
    <material name="neck_visual_material" rgba="0.55972 0.560028 0.558638 1"/>
    <material name="petg_2mm_headbracket_old_material" rgba="0.55972 0.560028 0.558638 1"/>
    <material name="camera_logitech_c920_offset_2mm_material" rgba="0.55972 0.560028 0.558638 1"/>
    <material name="camera_frame_material" rgba="0.55972 0.560028 0.558638 1"/>
    <material name="petg_2mm_rotatingheadbracket_material" rgba="0.55972 0.560028 0.558638 1"/>
    <material name="head_visual_material" rgba="0.55972 0.560028 0.558638 1"/>
    <material name="almi2_view_6_7__arm_bracket_material" rgba="0.55972 0.560028 0.558638 1"/>
    <material name="almi2_view_6_7__arm_bracket_visual_material" rgba="0.55972 0.560028 0.558638 1"/>
    <material name="almi2_view_13__14__arm_material" rgba="0.55972 0.560028 0.558638 1"/>
    <material name="right_upperhand_visual_material" rgba="0.55972 0.560028 0.558638 1"/>
    <material name="almi_4_5mm_connector_lower_arm_kidsize_material" rgba="0.55972 0.560028 0.558638 1"/>
    <material name="carbon_2mm_arm_kidsize_1_material" rgba="0.55972 0.560028 0.558638 1"/>
    <material name="tpu_arm_kidsize_telapak_material" rgba="0.55972 0.560028 0.558638 1"/>
    <material name="carbon_2mm_arm_kidsize_2_material" rgba="0.55972 0.560028 0.558638 1"/>
    <material name="right_lowerhand_visual_material" rgba="0.55972 0.560028 0.558638 1"/>
    <material name="almi2_view_6_7__arm_bracket_2_visual_material" rgba="0.55972 0.560028 0.558638 1"/>
    <material name="left_upperhand_visual_material" rgba="0.55972 0.560028 0.558638 1"/>
    <material name="left_lowerhand_visual_material" rgba="0.55972 0.560028 0.558638 1"/>
    <material name="stainless_steel_2mm_upper_leg_bracket_material" rgba="0.55972 0.560028 0.558638 1"/>
    <material name="stainless_steel_2mm_upper_leg_bracket_visual_material" rgba="0.55972 0.560028 0.558638 1"/>
    <material name="mx_64t_2_material" rgba="0.55972 0.560028 0.558638 1"/>
    <material name="almi_2mm_fr05_f101k_set_material" rgba="0.55972 0.560028 0.558638 1"/>
    <material name="almi_2mm_connector_mx64_material" rgba="0.55972 0.560028 0.558638 1"/>
    <material name="fr05_f101k_set_material" rgba="0.55972 0.560028 0.558638 1"/>
    <material name="mf128zz_1_material" rgba="0.55972 0.560028 0.558638 1"/>
    <material name="rx64_cap_1_material" rgba="0.55972 0.560028 0.558638 1"/>
    <material name="hn05_i101_1_material" rgba="0.55972 0.560028 0.558638 1"/>
    <material name="foot_right_1_visual_material" rgba="0.55972 0.560028 0.558638 1"/>
    <material name="stainless_steel_2mm__femur_material" rgba="0.55972 0.560028 0.558638 1"/>
    <material name="almi_6_5mm_l_mx64_material" rgba="0.55972 0.560028 0.558638 1"/>
    <material name="mx_64t_1_material" rgba="0.55972 0.560028 0.558638 1"/>
    <material name="hn05_i101_material" rgba="0.55972 0.560028 0.558638 1"/>
    <material name="mf128zz_material" rgba="0.55972 0.560028 0.558638 1"/>
    <material name="rx64_cap_material" rgba="0.55972 0.560028 0.558638 1"/>
    <material name="foot_right_2_visual_material" rgba="0.55972 0.560028 0.558638 1"/>
    <material name="stainless_steel_2mm_leg_spacer_material" rgba="0.55972 0.560028 0.558638 1"/>
    <material name="stainless_steel_2mm_shinebone_material" rgba="0.55972 0.560028 0.558638 1"/>
    <material name="foot_right_3_visual_material" rgba="0.55972 0.560028 0.558638 1"/>
    <material name="mx_64t_3_material" rgba="0.55972 0.560028 0.558638 1"/>
    <material name="fr05_f101k_set_1_material" rgba="0.55972 0.560028 0.558638 1"/>
    <material name="almi_2mm_connector_mx64_1_material" rgba="0.55972 0.560028 0.558638 1"/>
    <material name="almi_2mm_fr05_f101k_set_1_material" rgba="0.55972 0.560028 0.558638 1"/>
    <material name="hn05_i101_2_material" rgba="0.55972 0.560028 0.558638 1"/>
    <material name="mf128zz_2_material" rgba="0.55972 0.560028 0.558638 1"/>
    <material name="rx64_cap_2_material" rgba="0.55972 0.560028 0.558638 1"/>
    <material name="foot_right_4_visual_material" rgba="0.55972 0.560028 0.558638 1"/>
    <material name="pla_50__shoes_material" rgba="0.55972 0.560028 0.558638 1"/>
    <material name="almi_2mm_lower_leg_material" rgba="0.55972 0.560028 0.558638 1"/>
    <material name="stainless_steel_2mm_lower_leg_bracket_material" rgba="0.55972 0.560028 0.558638 1"/>
    <material name="foot_right_5_visual_material" rgba="0.55972 0.560028 0.558638 1"/>
    <material name="stainless_steel_2mm_upper_leg_bracket_mir_material" rgba="0.55972 0.560028 0.558638 1"/>
    <material name="stainless_steel_2mm_upper_leg_bracket_mir_visual_material" rgba="0.55972 0.560028 0.558638 1"/>
    <material name="mx_64t_mir_1_material" rgba="0.55972 0.560028 0.558638 1"/>
    <material name="almi_2mm_fr05_f101k_set_mir_material" rgba="0.55972 0.560028 0.558638 1"/>
    <material name="almi_2mm_connector_mx64_mir_material" rgba="0.55972 0.560028 0.558638 1"/>
    <material name="fr05_f101k_set_mir_material" rgba="0.55972 0.560028 0.558638 1"/>
    <material name="mf128zz_mir_1_material" rgba="0.55972 0.560028 0.558638 1"/>
    <material name="hn05_i101_mir_1_material" rgba="0.55972 0.560028 0.558638 1"/>
    <material name="rx64_cap_mir_1_material" rgba="0.55972 0.560028 0.558638 1"/>
    <material name="foot_left_1_visual_material" rgba="0.55972 0.560028 0.558638 1"/>
    <material name="mx_64t_mir_material" rgba="0.55972 0.560028 0.558638 1"/>
    <material name="stainless_steel_2mm__femur_mir_material" rgba="0.55972 0.560028 0.558638 1"/>
    <material name="almi_6_5mm_l_mx64_mir_material" rgba="0.55972 0.560028 0.558638 1"/>
    <material name="hn05_i101_mir_material" rgba="0.55972 0.560028 0.558638 1"/>
    <material name="rx64_cap_mir_material" rgba="0.55972 0.560028 0.558638 1"/>
    <material name="mf128zz_mir_material" rgba="0.55972 0.560028 0.558638 1"/>
    <material name="foot_left_2_visual_material" rgba="0.55972 0.560028 0.558638 1"/>
    <material name="stainless_steel_2mm_shinebone_mir_material" rgba="0.55972 0.560028 0.558638 1"/>
    <material name="stainless_steel_2mm_leg_spacer_mir_material" rgba="0.55972 0.560028 0.558638 1"/>
    <material name="foot_left_3_visual_material" rgba="0.55972 0.560028 0.558638 1"/>
    <material name="mx_64t_mir_2_material" rgba="0.55972 0.560028 0.558638 1"/>
    <material name="almi_2mm_connector_mx64_mir_1_material" rgba="0.55972 0.560028 0.558638 1"/>
    <material name="fr05_f101k_set_mir_1_material" rgba="0.55972 0.560028 0.558638 1"/>
    <material name="almi_2mm_fr05_f101k_set_mir_1_material" rgba="0.55972 0.560028 0.558638 1"/>
    <material name="hn05_i101_mir_2_material" rgba="0.55972 0.560028 0.558638 1"/>
    <material name="mf128zz_mir_2_material" rgba="0.55972 0.560028 0.558638 1"/>
    <material name="rx64_cap_mir_2_material" rgba="0.55972 0.560028 0.558638 1"/>
    <material name="foot_left_4_visual_material" rgba="0.55972 0.560028 0.558638 1"/>
    <material name="almi_2mm_lower_leg_mir_material" rgba="0.55972 0.560028 0.558638 1"/>
    <material name="stainless_steel_2mm_lower_leg_bracket_mir_material" rgba="0.55972 0.560028 0.558638 1"/>
    <material name="pla_50__shoes_mir_material" rgba="0.55972 0.560028 0.558638 1"/>
    <material name="foot_left_5_visual_material" rgba="0.55972 0.560028 0.558638 1"/>
  </asset>
  <actuator>
    <position class="hiro-mujoco" name="neck_yaw" joint="neck_yaw" forcerange="-6.0 6.0" inheritrange="1"/>
    <position class="hiro-mujoco" name="neck_pitch" joint="neck_pitch" forcerange="-6.0 6.0" inheritrange="1"/>
    <position class="hiro-mujoco" name="right_shoulder_pitch" joint="right_shoulder_pitch" forcerange="-6.0 6.0" inheritrange="1"/>
    <position class="hiro-mujoco" name="right_shoulder_roll" joint="right_shoulder_roll" forcerange="-6.0 6.0" inheritrange="1"/>
    <position class="hiro-mujoco" name="right_elbow" joint="right_elbow" forcerange="-6.0 6.0" inheritrange="1"/>
    <position class="hiro-mujoco" name="left_shoulder_pitch" joint="left_shoulder_pitch" forcerange="-6.0 6.0" inheritrange="1"/>
    <position class="hiro-mujoco" name="left_shoulder_roll" joint="left_shoulder_roll" forcerange="-6.0 6.0" inheritrange="1"/>
    <position class="hiro-mujoco" name="left_elbow" joint="left_elbow" forcerange="-6.0 6.0" inheritrange="1"/>
    <position class="hiro-mujoco" name="right_hip_yaw" joint="right_hip_yaw" forcerange="-6.0 6.0" inheritrange="1"/>
    <position class="hiro-mujoco" name="right_hip_roll" joint="right_hip_roll" forcerange="-6.0 6.0" inheritrange="1"/>
    <position class="hiro-mujoco" name="right_hip_pitch" joint="right_hip_pitch" forcerange="-6.0 6.0" inheritrange="1"/>
    <position class="hiro-mujoco" name="right_knee" joint="right_knee" forcerange="-6.0 6.0" inheritrange="1"/>
    <position class="hiro-mujoco" name="right_ankle_pitch" joint="right_ankle_pitch" forcerange="-6.0 6.0" inheritrange="1"/>
    <position class="hiro-mujoco" name="right_ankle_roll" joint="right_ankle_roll" forcerange="-6.0 6.0" inheritrange="1"/>
    <position class="hiro-mujoco" name="left_hip_yaw" joint="left_hip_yaw" forcerange="-6.0 6.0" inheritrange="1"/>
    <position class="hiro-mujoco" name="left_hip_roll" joint="left_hip_roll" forcerange="-6.0 6.0" inheritrange="1"/>
    <position class="hiro-mujoco" name="left_hip_pitch" joint="left_hip_pitch" forcerange="-6.0 6.0" inheritrange="1"/>
    <position class="hiro-mujoco" name="left_knee" joint="left_knee" forcerange="-6.0 6.0" inheritrange="1"/>
    <position class="hiro-mujoco" name="left_ankle_pitch" joint="left_ankle_pitch" forcerange="-6.0 6.0" inheritrange="1"/>
    <position class="hiro-mujoco" name="left_ankle_roll" joint="left_ankle_roll" forcerange="-6.0 6.0" inheritrange="1"/>
  </actuator>

  <sensor>
    <gyro name="gyro_sensor" site="torso_imu_site"/>
    <accelerometer name="accel_sensor" site="torso_imu_site"/>
  </sensor>
  <equality/>
</mujoco>
